<?xml version="1.0" ?>
<!-- =================================================================================== -->
<!-- |    This document was autogenerated by xacro from /home/bot/catkin_ws/src/phoebe_stack/phoebe_description/phoebe.urdf.xacro | -->
<!-- |    EDITING THIS FILE BY HAND IS NOT RECOMMENDED                                 | -->
<!-- =================================================================================== -->
<robot name="phoebe" xmlns:xacro="http://www.ros.org/wiki/xacro">
  
  <!-- bot base Pioneer 3-DX for Performance Peoplebot -->
  <link name="bot_base_link">
    <inertial>
      <origin rpy="0 0 0" xyz="-0.04 0.0 0.207"/>
      <mass value="14.3"/>
      <!-- inretia tensor for solid cuboid: m=15, h=0.24, d=0.45, w=0.39 -->
      <inertia ixx="0.2621" ixy="0" ixz="0" iyy="0.3195" iyz="0" izz="0.4377"/>
    </inertial>
    <visual>
      <origin rpy="0 0 0" xyz="-0.04 0.0 0.207"/>
      <geometry>
        <mesh filename="package://phoebe_description/meshes/bot_base_new_v6.stl" scale="0.001 0.001 0.001"/>
      </geometry>
    </visual>
    <collision>
      <origin rpy="0 0 0" xyz="-0.04 0.0 0.207"/>
      <geometry>
        <mesh filename="package://phoebe_description/meshes/bot_base_new_v6.stl" scale="0.001 0.001 0.001"/>
      </geometry>
    </collision>
  </link>

<!-- wheels -->

  <joint name="wheel_left_joint" type="continuous">
    <parent link="bot_base_link"/>
    <child link="wheel_left_link"/>
    <origin rpy="-1.57 0 0" xyz="0.0 -0.172 0.095"/>
    <axis xyz="0 0 1"/>
  </joint>
  <link name="wheel_left_link">
    <inertial>
      <origin rpy="1.57 0 0" xyz="0 0 0"/>
      <mass value="0.5"/>
      <!-- inertia tensor for solid cylinder: m=0.5, h=0.05, r=0.095 -->
      <!-- inertia calculation: 
        ixx = (m*(h^2 + 3*r^2)) / 12
        ixy = 0
        ixz = 0
        iyy = (m*(h^2 + 3*r^2)) / 12
        iyz = 0
        izz = (m*r^2) / 2
      -->
      <inertia ixx="1.232291667e-03" ixy="0" ixz="0" iyy="1.232291667e-03" iyz="0" izz="2.25625e-03"/>
    </inertial>
    <visual>
      <origin rpy="1.57 0 0" xyz="0 0 0"/>
      <geometry>
        <mesh filename="package://phoebe_description/meshes/wheel.stl" scale="0.001 0.001 0.001"/>
      </geometry>
      <material name="blackish">
        <color rgba="0.2 0.2 0.2 1"/>
      </material>
    </visual>
    <collision>
      <origin rpy="0 0 0" xyz="0 0 0"/>
      <geometry>
        <cylinder length="0.05" radius="0.095"/>
      </geometry>
    </collision>

  </link>
  
  <joint name="wheel_right_joint" type="continuous">
    <parent link="bot_base_link"/>
    <child link="wheel_right_link"/>
    <origin rpy="-1.57 0 0" xyz="0.0 0.172 0.095"/>
    <axis xyz="0 0 1"/>
  </joint>
  <link name="wheel_right_link">
    <inertial>
      <origin rpy="1.57 0 0" xyz="0 0 0"/>
      <mass value="0.5"/>
      <!-- inretia tensor for solid cylinder: m=0.5, h=0.05, r=0.095 -->
      <inertia ixx="1.232291667e-03" ixy="0" ixz="0" iyy="1.232291667e-03" iyz="0" izz="2.25625e-03"/>
    </inertial>
    <visual>
      <origin rpy="1.57 0 0" xyz="0 0 0"/>
      <geometry>
        <mesh filename="package://phoebe_description/meshes/wheel.stl" scale="0.001 0.001 0.001"/>
      </geometry>
      <material name="blackish">
        <color rgba="0.2 0.2 0.2 1"/>
      </material>
    </visual>
    <collision>
      <origin rpy="0 0 0" xyz="0 0 0"/>
      <geometry>
        <cylinder length="0.05" radius="0.095"/>
      </geometry>
    </collision>

  </link>

  <!-- caster wheel -->

  <joint name="caster_base_plate_joint" type="fixed">
    <parent link="bot_base_link"/>
    <child link="caster_base_plate"/>
    <origin rpy="3.14159 0 0" xyz="-0.185 0 0.1"/>
  </joint>
  <link name="caster_base_plate">
    <inertial>
      <origin xyz="0 0 0"/>
      <mass value="0.2"/>
      <inertia ixx="0.0001668" ixy="0" ixz="0" iyy="0.0001668" iyz="0" izz="0.0003"/>
    </inertial>
    <visual>
      <origin xyz="0 0 0"/>
      <geometry>
        <mesh filename="package://phoebe_description/meshes/caster_wheel_base_plate_v1.stl" scale="0.001 0.001 0.001"/>
      </geometry>
      <material name="black">
        <color rgba="0.2 0.2 0.2 1"/>
      </material>
    </visual>
    <collision>
      <origin  xyz="0 0 0"/>
      <geometry>
        <mesh filename="package://phoebe_description/meshes/caster_wheel_base_plate_v1.stl" scale="0.001 0.001 0.001"/>
      </geometry>
    </collision>
  </link>

  <joint name="caster_swivel_joint" type="continuous">
    <parent link="caster_base_plate"/>
    <child link="caster_fork"/>
    <origin rpy="0.0 0 0" xyz="0 0 0.003"/>
    <axis xyz="0 0 1"/>
  </joint>
  <link name="caster_fork">
    <inertial>
      <origin xyz="0 0 0"/>
      <mass value="0.3"/>
      <inertia ixx="0.0004578" ixy="0" ixz="0" iyy="0.0004578" iyz="0" izz="0.00075"/>
    </inertial>
    <visual>
      <origin rpy="0 0 0" xyz="0 0 0"/>
      <geometry>
        <mesh filename="package://phoebe_description/meshes/caster_wheel_fork_v3.stl" scale="0.001 0.001 0.001"/>
      </geometry>
    </visual>
    <collision>
      <origin  xyz="0 0 0"/>
      <geometry>
        <mesh filename="package://phoebe_description/meshes/caster_wheel_fork_v3.stl" scale="0.001 0.001 0.001"/>
      </geometry>
    </collision>
  </link> 

  <joint name="caster_wheel_joint" type="continuous">
    <parent link="caster_fork"/>
    <child link="caster_wheel"/>
    <origin rpy="0 0 0" xyz="-0.0275 0 0.069"/>
    <axis xyz="0 1 0"/>
  </joint>
  <link name="caster_wheel">
    <inertial>
      <origin xyz="0 0 0"/>
      <mass value="0.2"/>
      <inertia ixx="0.000055717" ixy="0" ixz="0" iyy="0.000055717" iyz="0" izz="0.0000729"/>
    </inertial>
    <visual>
      <origin rpy="0 0 0" xyz="0 0 0"/>
      <geometry>
        <mesh filename="package://phoebe_description/meshes/caster_wheel_3.stl" scale="0.0009 0.0009 0.0009"/>
      </geometry>
    </visual>
    <collision>
      <origin  xyz="0 0 0"/>
      <geometry>
        <mesh filename="package://phoebe_description/meshes/caster_wheel_3.stl" scale="0.0009 0.0009 0.0009"/>
      </geometry>
    </collision>
  </link>

<!-- Side posts -->

  <joint name="left_side_post_attachment_joint" type="fixed">
    <parent link="bot_base_link"/>
    <child link="left_side_post"/>
    <origin rpy="0.0 -0.03 0.0" xyz="0.0 0.172 0.095"/>
  </joint>
  <link name="left_side_post">
    <inertial>
      <origin rpy="0 0 0" xyz="0.0 0.0 0.0"/>
      <mass value="4"/>
      <inertia ixx="0.3906" ixy="0" ixz="0" iyy="0.4056" iyz="0" izz="0.0186"/>
    </inertial>
    <visual>
      <origin rpy="0 0 0" xyz="0 0 0.0"/>
      <geometry>
        <mesh filename="package://phoebe_description/meshes/side_pillar_v2.stl" scale="0.001 0.001 0.001"/>
      </geometry>
    </visual>
    <collision>
      <origin rpy="0 0 0" xyz="0 0 0.0"/>
      <geometry>
        <mesh filename="package://phoebe_description/meshes/side_pillar_v2.stl" scale="0.001 0.001 0.001"/>
      </geometry>
    </collision>
  </link>

  <joint name="right_side_post_attachment_joint" type="fixed">
    <parent link="bot_base_link"/>
    <child link="right_side_post"/>
    <origin rpy="0.0 -0.03 0.0" xyz="0.0 -0.172 0.095"/>
  </joint>
  <link name="right_side_post">
    <inertial>
      <origin rpy="0 0 0" xyz="0.0 0.0 0.0"/>
      <mass value="4"/>
      <inertia ixx="0.3906" ixy="0" ixz="0" iyy="0.4056" iyz="0" izz="0.0186"/>
    </inertial>
    <visual>
      <origin rpy="0 0 0" xyz="0 0 0.0"/>
      <geometry>
        <mesh filename="package://phoebe_description/meshes/side_pillar_v2.stl" scale="0.001 0.001 0.001"/>
      </geometry>
    </visual>
    <collision>
      <origin rpy="0 0 0" xyz="0 0 0.0"/>
      <geometry>
        <mesh filename="package://phoebe_description/meshes/side_pillar_v2.stl" scale="0.001 0.001 0.001"/>
      </geometry>
    </collision>
  </link>

<!-- Top lidar plate -->
  <joint name="top_lidar_attachment_joint" type="fixed">
    <parent link="left_side_post"/>
    <child link="top_lidar_link"/>
    <origin rpy="0 0 0" xyz="-0.092 -0.1695 0.953"/>
  </joint>
  <link name="top_lidar_link">
    <inertial>
      <origin rpy="0 0 0" xyz="0 0 0"/>
      <mass value="2"/>
      <inertia ixx="0.0126" ixy="0" ixz="0" iyy="0.0245" iyz="0" izz="0.0362"/>
    </inertial>
    <visual>
      <origin rpy="0 0 0" xyz="0 0 0.0"/>
      <geometry>
        <mesh filename="package://phoebe_description/meshes/top_lidar_component_new_v4.stl" scale="0.001 0.001 0.001"/>
      </geometry>
    </visual>
    <collision>
      <origin rpy="0 0 0" xyz="0 0 0.0"/>
      <geometry>
        <mesh filename="package://phoebe_description/meshes/top_lidar_component_new_v4.stl" scale="0.001 0.001 0.001"/>
      </geometry>
    </collision>
  </link>

<!-- Central plate and arm attachment plate -->
  <joint name="central_plate_joint" type="fixed">
    <parent link="left_side_post"/>
    <child link="central_plate"/>
    <origin rpy="1.57 0 -1.57" xyz="-0.025 -0.013 0.14"/>
  </joint>
  <link name="central_plate">
    <inertial>
      <origin rpy="0 0 0" xyz="0 0 0"/>
      <mass value="4.66"/>
      <inertia ixx="0.1938" ixy="0" ixz="0" iyy="0.1625" iyz="0" izz="0.0312"/>
    </inertial>
    <visual>
      <origin rpy="0 0 0" xyz="0 0 0"/>
      <geometry>
        <mesh filename="package://phoebe_description/meshes/central_plate_v1.stl" scale="0.001 0.001 0.001"/>
      </geometry>
    </visual>
    <collision>
      <origin rpy="0 0 0" xyz="0 0 0"/>
      <geometry>
        <mesh filename="package://phoebe_description/meshes/central_plate_v1.stl" scale="0.001 0.001 0.001"/>
      </geometry>
    </collision>
  </link>

    <joint name="arm_attachment_plate_joint" type="fixed">
    <parent link="central_plate"/>
    <child link="arm_attachment_plate"/>
    <origin rpy="3.14159 0 0" xyz="0.16 0.74 0"/>
  </joint>
  <link name="arm_attachment_plate">
    <inertial>
      <origin rpy="0 0 0" xyz="0 0 0"/>
      <mass value="1.66"/>
      <inertia ixx="0.0138" ixy="0" ixz="0" iyy="0.0045" iyz="0" izz="0.0096"/>
    </inertial>
    <visual>
      <origin rpy="0 0 0" xyz="0 0 0"/>
      <geometry>
        <mesh filename="package://phoebe_description/meshes/arm_attachment_plate_v1.stl" scale="0.001 0.001 0.001"/>
      </geometry>
    </visual>
    <collision>
      <origin rpy="0 0 0" xyz="0 0 0"/>
      <geometry>
        <mesh filename="package://phoebe_description/meshes/arm_attachment_plate_v1.stl" scale="0.001 0.001 0.001"/>
      </geometry>
    </collision>
  </link>

<!-- Bumper plates -->
  <joint name="front_bumper_plate_joint" type="fixed">
    <parent link="bot_base_link"/>
    <child link="front_bumper_plate"/>
    <origin rpy="0 0 1.57" xyz="0.205 0 0.057"/>
  </joint>
  <link name="front_bumper_plate">
    <inertial>
      <origin rpy="0 0 0" xyz="0 0 0"/>
      <mass value="1"/>
      <!-- interial tensor for plate with w=0.41, d=0.115, h=0.002 and m=1 -->
      <inertia ixx="0.0140" ixy="0" ixz="0" iyy="0.0011" iyz="0" izz="0.0151"/>
    </inertial>
    <visual>
      <origin rpy="0 0 0" xyz="0 0 0"/>
      <geometry>
        <mesh filename="package://phoebe_description/meshes/front_bumper_plate_v5.stl" scale="0.001 0.001 0.001"/>
      </geometry>
    </visual>
    <collision>
      <origin rpy="0 0 0" xyz="0 0 0"/>
      <geometry>
        <mesh filename="package://phoebe_description/meshes/front_bumper_plate_v5.stl" scale="0.001 0.001 0.001"/>
      </geometry>
    </collision>
  </link>

  <joint name="back_bumper_plate_joint" type="fixed">
    <parent link="bot_base_link"/>
    <child link="back_bumper_plate"/>
    <origin rpy="0 0 -1.57" xyz="-0.2 0 0.057"/>
  </joint>
  <link name="back_bumper_plate">
    <inertial>
      <origin rpy="0 0 0" xyz="0 0 0"/>
      <mass value="0.7"/>
      <!-- inertial tensor for plate with w=0.38, d=0.165, h=0.002 and m=0.7 -->
      <inertia ixx="0.0120" ixy="0" ixz="0" iyy="0.0023" iyz="0" izz="0.0143"/>
    </inertial>
    <visual>
      <origin rpy="0 0 0" xyz="0 0 0"/>
      <geometry>
        <mesh filename="package://phoebe_description/meshes/back_bumper_plate_v1.stl" scale="0.001 0.001 0.001"/>
      </geometry>
    </visual>
    <collision>
      <origin rpy="0 0 0" xyz="0 0 0"/>
      <geometry>
        <mesh filename="package://phoebe_description/meshes/back_bumper_plate_v1.stl" scale="0.001 0.001 0.001"/>
      </geometry>
    </collision>
  </link>

<!-- Cyton Gamma 1500 models -->

<!-- Right arm -->
	
  <joint name="right_arm_joint" type="fixed">
    <parent link="arm_attachment_plate"/>
    <child link="right_arm_bot_base_link"/>
    <origin rpy="-1.57 0 -1.57" xyz="0.0015 0.075 0.1"/>
  </joint>
  <link name="right_arm_bot_base_link">
    <inertial>
      <origin rpy="0 0 0" xyz="0.0 0 0"/>
      <mass value="0.478571"/>
      <!-- inretia tensor for solid cuboid: m=0.478571, w=0.177, h=0.074, d=0.150 -->
      <inertia ixx="1.47e-03" ixy="0" ixz="0" iyy="2.15e-03" iyz="0" izz="1.12e-03"/>
    </inertial>
    <visual>
      <origin rpy="0 0 0" xyz="0 0 0"/>
      <geometry>
        <mesh filename="package://cyton_gamma_1500_description/meshes/base.dae"/>
      </geometry>
    </visual>
    <collision>
      <origin xyz="0 0 0" rpy="0 0 0"/>
      <geometry>
        <mesh filename="package://cyton_gamma_1500_description/meshes/base.dae"/>
      </geometry>
    </collision>
  </link>

  <joint name="right_arm_shoulder_roll_joint" type="revolute">
    <parent link="right_arm_bot_base_link"/>
    <child link="right_arm_shoulder_roll"/>
    <origin rpy="0 0 0" xyz="0 0 0.05315"/>
    <limit effort="100.0" lower="-2.618" upper="2.618" velocity="1.0"/>
    <axis xyz="0 0 1"/>
  </joint>
  <link name="right_arm_shoulder_roll">
    <inertial>
      <origin rpy="0 0 0" xyz="0 0 0.12"/>
      <mass value="0.468571"/>
      <!-- inretia tensor for solid cylinder: m=0.468571, h=0.09248, r=0.044737 -->
      <inertia ixx="4.7e-04" ixy="0" ixz="0" iyy="5.7e-04" iyz="0" izz="5.7e-04"/>
    </inertial>
    <visual>
      <origin rpy="1.5708 0 0.384" xyz="0 0 0"/>
      <geometry>
        <mesh filename="package://cyton_gamma_1500_description/meshes/shoulder_roll.dae"/>
      </geometry>
    </visual>
    <collision>
      <origin rpy="1.5708 0 0.384" xyz="0 0 0"/>
      <geometry>
        <mesh filename="package://cyton_gamma_1500_description/meshes/shoulder_roll.dae"/>
      </geometry>
    </collision>
  </link>

  <joint name="right_arm_shoulder_pitch_joint" type="revolute">
    <parent link="right_arm_shoulder_roll"/>
    <child link="right_arm_shoulder_pitch"/>
    <origin rpy="0 0 0" xyz="0.0205 0 0.12435"/>
    <limit effort="100.0" lower="-1.8326" upper="1.8326" velocity="1.0"/>
    <axis xyz="1 0 0"/>
  </joint>
  <link name="right_arm_shoulder_pitch">
    <inertial>
      <origin rpy="0 0 0" xyz="-0.0214 0 0.117"/>
      <mass value="0.4285714"/>
      <!-- inretia tensor for solid cylinder: m=0.4285714, h=0.09248, r=0.04204 -->
      <inertia ixx="4.9e-04" ixy="0" ixz="0" iyy="3.8e-04" iyz="0" izz="4.9e-04"/>
    </inertial>
    <visual>
      <origin rpy="1.5708 0 0" xyz="0 0 0"/>
      <geometry>
        <mesh filename="package://cyton_gamma_1500_description/meshes/shoulder_pitch.dae"/>
      </geometry>
    </visual>
    <collision>
      <origin rpy="1.5708 0 0" xyz="0 0 0"/>
      <geometry>
        <mesh filename="package://cyton_gamma_1500_description/meshes/shoulder_pitch.dae"/>
      </geometry>
    </collision>
  </link>

  <joint name="right_arm_shoulder_yaw_joint" type="revolute">
    <parent link="right_arm_shoulder_pitch"/>
    <child link="right_arm_shoulder_yaw"/>
    <origin rpy="0 0 0" xyz="-0.0215 -0.0205 0.1255"/>
    <limit effort="100.0" lower="-1.8326" upper="1.8326" velocity="1.0"/>
    <axis xyz="0 -1 0"/>
  </joint>
  <link name="right_arm_shoulder_yaw">
    <inertial>
      <origin rpy="0 0 0" xyz="-0.002 0.021 0.1135"/>
      <mass value="0.408571"/>
      <!-- inretia tensor for solid cylinder: m=0.408571, h=0.084081, r=0.036785 -->
      <inertia ixx="2.8e-04" ixy="0" ixz="0" iyy="3.8e-04" iyz="0" izz="3.8e-04"/>
    </inertial>
    <visual>
      <origin rpy="1.5708 0 -1.5708" xyz="0 0 0.0"/>
      <geometry>
        <mesh filename="package://cyton_gamma_1500_description/meshes/shoulder_yaw.dae"/>
      </geometry>
    </visual>
    <collision>
      <origin rpy="1.5708 0 -1.5708" xyz="0 0 0"/>
      <geometry>
        <mesh filename="package://cyton_gamma_1500_description/meshes/shoulder_yaw.dae"/>
      </geometry>
    </collision>
  </link>

  <joint name="right_arm_elbow_pitch_joint" type="revolute">
    <parent link="right_arm_shoulder_yaw"/>
    <child link="right_arm_elbow_pitch"/>
    <origin rpy="0 0 0" xyz="0.018 0.0206 0.1158"/>
    <limit effort="1000.0" lower="-1.8326" upper="1.8326" velocity="1.0"/>
    <axis xyz="1 0 0"/>
  </joint>
  <link name="right_arm_elbow_pitch">
    <inertial>
      <origin rpy="0 0 0" xyz="-0.0176 0.001 0.095"/>
      <mass value="0.388671"/>
      <!-- inretia tensor for solid cylinder: m=0.388671, h=0.06705, r=0.028975 -->
      <inertia ixx="2.3e-04" ixy="0" ixz="0" iyy="1.6e-04" iyz="0" izz="2.3e-04"/>
    </inertial>
    <visual>
      <origin rpy="1.5708 0 3.1416" xyz="0 0 0"/>
      <geometry>
        <mesh filename="package://cyton_gamma_1500_description/meshes/elbow_pitch.dae"/>
      </geometry>
    </visual>
    <collision>
      <origin rpy="1.5708 0 3.1416" xyz="0 0 0"/>
      <geometry>
        <mesh filename="package://cyton_gamma_1500_description/meshes/elbow_pitch.dae"/>
      </geometry>
    </collision>
  </link>

  <joint name="right_arm_elbow_yaw_joint" type="revolute">
    <parent link="right_arm_elbow_pitch"/>
    <child link="right_arm_elbow_yaw"/>
    <origin rpy="0 0 0" xyz="-0.0171 -0.018 0.09746"/>
    <limit effort="1000.0" lower="-1.8326" upper="1.8326" velocity="1.0"/>
    <axis xyz="0 -1 0"/>
  </joint>
  <link name="right_arm_elbow_yaw">
    <inertial>
      <origin rpy="0 0 0" xyz="0 0.018 0.073"/>
      <mass value="0.368871"/>
      <!-- inretia tensor for solid cylinder: m=0.368871, h=0.043602, r=0.024071 -->
      <inertia ixx="1.0686e-04" ixy="0" ixz="0" iyy="1.1187e-04" iyz="0" izz="1.1187e-04"/>
    </inertial>
    <visual>
      <origin rpy="1.5708 0 1.5708" xyz="0 0 0"/>
      <geometry>
        <mesh filename="package://cyton_gamma_1500_description/meshes/elbow_yaw.dae"/>
      </geometry>
    </visual>
    <collision>
      <origin rpy="1.5708 0 1.5708" xyz="0 0 0"/>
      <geometry>
        <mesh filename="package://cyton_gamma_1500_description/meshes/elbow_yaw.dae"/>
      </geometry>
    </collision>
  </link>

  <joint name="right_arm_wrist_pitch_joint" type="revolute">
    <parent link="right_arm_elbow_yaw"/>
    <child link="right_arm_wrist_pitch"/>
    <origin rpy="0 0 0" xyz="0.02626 0.018 0.0718"/>
    <limit effort="100.0" lower="-1.8326" upper="1.8326" velocity="1.0"/>
    <axis xyz="-1 0 0"/>
  </joint>
  <link name="right_arm_wrist_pitch">
    <inertial>
      <origin rpy="0 0 0" xyz="-0.027 -0.0005 0.028"/>
      <mass value="0.008"/>
      <!-- inretia tensor for solid cuboid: m=0.008, h=0.045602, w=0.0218, d=0.005 -->
      <inertia ixx="3.3349e-07" ixy="0" ixz="0" iyy="1.403e-06" iyz="0" izz="1.70319e-06"/>
    </inertial>
    <visual>
      <origin rpy="1.5708 0 1.5708" xyz="0 0 0"/>
      <geometry>
        <mesh filename="package://cyton_gamma_1500_description/meshes/wrist_pitch.dae"/>
      </geometry>
    </visual>
    <collision>
      <origin rpy="1.5708 0 1.5708" xyz="0 0 0"/>
      <geometry>
        <mesh filename="package://cyton_gamma_1500_description/meshes/wrist_pitch.dae"/>
      </geometry>
    </collision>
  </link>  

  <joint name="right_arm_wrist_roll_joint" type="revolute">
    <parent link="right_arm_wrist_pitch"/>
    <child link="right_arm_wrist_roll"/>
    <origin rpy="0 0 0" xyz="-0.026255 0 0.051425"/>
    <limit effort="100.0" lower="-2.61799" upper="2.61799" velocity="1.0"/>
    <axis xyz="0 0 1"/>
  </joint>
  <link name="right_arm_wrist_roll">
    <inertial>
      <origin rpy="0 0 0" xyz="0 0 0.029"/>
      <mass value="0.38"/>
      <!-- inretia tensor for solid cylinder: m=0.38, h=0.095, r=0.027975 -->
      <inertia ixx="3.6e-04" ixy="0" ixz="0" iyy="3.6e-04" iyz="0" izz="1.487e-04"/>
    </inertial>
    <visual>
      <origin rpy="3.1416 0 -1.5708" xyz="0 0 0"/>
      <geometry>
        <mesh filename="package://cyton_gamma_1500_description/meshes/wrist_roll.dae"/>
      </geometry>
    </visual>
    <collision>
      <origin rpy="3.1416 0 -1.5708" xyz="0 0 0"/>
      <geometry>
        <mesh filename="package://cyton_gamma_1500_description/meshes/wrist_roll.dae"/>
      </geometry>
    </collision>
  </link>

  <joint name="right_arm_gripper_joint" type="prismatic">
    <parent link="right_arm_wrist_roll"/>
    <child link="right_arm_gripper_finger1"/>
    <origin rpy="0 0 0" xyz="-0.01331 0.00485 0.077225"/>
    <limit effort="100.0" lower="-0.008" upper="0.008" velocity="1.0"/>
    <axis xyz="1 0 0"/>
  </joint>
  <link name="right_arm_gripper_finger1">
    <inertial>
      <origin rpy="0 0 0" xyz="-0.0036 0.0096 0.017"/>
      <mass value="0.035"/>
      <!-- inretia tensor for solid cuboid: m=0.035, h=0.0323, w=0.01469, d=0.0224 -->
      <inertia ixx="4.5064e-06" ixy="0" ixz="0" iyy="3.6723e-06" iyz="0" izz="2.0929e-06"/>
    </inertial>
    <visual>
      <origin rpy="0 0 0" xyz="0 0 0"/>
      <geometry>
        <mesh filename="package://cyton_gamma_1500_description/meshes/gripper_finger1.dae"/>
      </geometry>
    </visual>
    <collision>
      <origin rpy="0 0 0" xyz="0 0 0"/>
      <geometry>
        <mesh filename="package://cyton_gamma_1500_description/meshes/gripper_finger1.dae"/>
      </geometry>
    </collision>
  </link>

  <joint name="right_arm_gripper_joint2" type="prismatic">
    <parent link="right_arm_wrist_roll"/>
    <child link="right_arm_gripper_finger2"/>
    <origin rpy="0 0 0" xyz="0.0098 0.00485 0.077225"/>
    <limit effort="100.0" lower="-0.008" upper="0.008" velocity="1.0"/>
    <mimic joint="right_arm_gripper_joint" multiplier="-1"/>
    <axis xyz="1 0 0"/>
  </joint>
  <link name="right_arm_gripper_finger2">
    <inertial>
      <origin rpy="0 0 0" xyz="0.0034 0.0096 0.017"/>
      <mass value="0.035"/>
      <!-- inretia tensor for solid cuboid: m=0.035, h=0.0323, w=0.01469, d=0.0224 -->
      <inertia ixx="4.5064e-06" ixy="0" ixz="0" iyy="3.6723e-06" iyz="0" izz="2.0929e-06"/>
    </inertial>
    <visual>
      <origin rpy="0 0 0" xyz="0 0 0"/>
      <geometry>
        <mesh filename="package://cyton_gamma_1500_description/meshes/gripper_finger2.dae"/>
      </geometry>
    </visual>
    <collision>
      <origin rpy="0 0 0" xyz="0 0 0"/>
      <geometry>
        <mesh filename="package://cyton_gamma_1500_description/meshes/gripper_finger2.dae"/>
      </geometry>
    </collision>
  </link>

  <!-- camera and camera bracket -->
  <joint name="right_arm_camera_bracket_joint" type="fixed">
    <parent link="right_arm_wrist_roll"/>
    <child link="right_arm_camera_bracket"/>
    <origin rpy="0 0 0" xyz="-0.0008 -0.028 0.0435"/>
  </joint>
  <link name="right_arm_camera_bracket">
    <inertial>
      <origin rpy="0.95 0 0" xyz="0 -0.01 -0.012"/>
      <mass value="0.052"/>
      <!-- inretia tensor for solid cuboid: m=0.052, h=0.071, w=0.028, d=0.0086 -->
      <inertia ixx="2.2165e-05" ixy="0" ixz="0" iyy="3.7178e-06" iyz="0" izz="2.5242e-05"/>
    </inertial>
    <visual>
      <origin rpy="0 0 0" xyz="0 0 0"/>
      <geometry>
        <mesh filename="package://cyton_gamma_1500_minicam_description/meshes/cam_bracket.dae"/>
      </geometry>
    </visual>
    <collision>
      <origin rpy="0 0 0" xyz="0 0 0"/>
      <geometry>
        <mesh filename="package://cyton_gamma_1500_minicam_description/meshes/cam_bracket.dae"/>
      </geometry>
    </collision>
  </link>

  <joint name="right_arm_camera_joint" type="fixed">
    <parent link="right_arm_camera_bracket"/>
    <child link="right_arm_camera"/>
    <origin rpy="-0.625 0 0" xyz="0.0 -0.028 -0.005"/>
  </joint>
  <link name="right_arm_camera">
    <inertial>
      <origin rpy="0 0 0" xyz="0 0 0"/>
      <mass value="0.085"/>
      <!-- inretia tensor for solid cuboid: m=0.085, h=0.065, w=0.024, d=0.024 -->
      <inertia ixx="3.4007e-05" ixy="0" ixz="0" iyy="3.4007e-05" iyz="0" izz="8.16e-06"/>
    </inertial>
    <visual>
      <origin rpy="0 0 0" xyz="0 0 0"/>
      <geometry>
        <box size="0.031 0.028 0.063"/>
      </geometry>
      <material name="blackish">
        <color rgba="0.2 0.2 0.2 1"/>
      </material>
    </visual>
    <collision>
      <origin rpy="0 0 0" xyz="0 0 0"/>
      <geometry>
        <box size="0.036 0.045 0.063"/>
      </geometry>
    </collision>
  </link>

<!-- Left arm -->

  <joint name="left_arm_joint" type="fixed">
    <parent link="arm_attachment_plate"/>
    <child link="left_arm_bot_base_link"/>
    <origin rpy="-1.57 0 1.57" xyz="-0.0015 0.075 0.1"/>
  </joint>
  <link name="left_arm_bot_base_link">
    <inertial>
      <origin rpy="0 0 0" xyz="0.0 0 0"/>
      <mass value="0.478571"/>
      <!-- inretia tensor for solid cuboid: m=0.478571, w=0.177, h=0.074, d=0.150 -->
      <inertia ixx="1.47e-03" ixy="0" ixz="0" iyy="2.15e-03" iyz="0" izz="1.12e-03"/>
    </inertial>
    <visual>
      <origin rpy="0 0 0" xyz="0 0 0"/>
      <geometry>
        <mesh filename="package://cyton_gamma_1500_description/meshes/base.dae"/>
      </geometry>
    </visual>
    <collision>
      <origin xyz="0 0 0" rpy="0 0 0"/>
      <geometry>
        <mesh filename="package://cyton_gamma_1500_description/meshes/base.dae"/>
      </geometry>
    </collision>
  </link>

  <joint name="left_arm_shoulder_roll_joint" type="revolute">
    <parent link="left_arm_bot_base_link"/>
    <child link="left_arm_shoulder_roll"/>
    <origin rpy="0 0 0" xyz="0 0 0.05315"/>
    <limit effort="1000.0" lower="-2.618" upper="2.618" velocity="1.0"/>
    <axis xyz="0 0 1"/>
  </joint>
  <link name="left_arm_shoulder_roll">
    <inertial>
      <origin rpy="0 0 0" xyz="0 0 0.12"/>
      <mass value="0.468571"/>
      <!-- inretia tensor for solid cylinder: m=0.468571, h=0.09248, r=0.044737 -->
      <inertia ixx="4.7e-04" ixy="0" ixz="0" iyy="5.7e-04" iyz="0" izz="5.7e-04"/>
    </inertial>
    <visual>
      <origin rpy="1.5708 0 0.384" xyz="0 0 0"/>
      <geometry>
        <mesh filename="package://cyton_gamma_1500_description/meshes/shoulder_roll.dae"/>
      </geometry>
    </visual>
    <collision>
      <origin rpy="1.5708 0 0.384" xyz="0 0 0"/>
      <geometry>
        <mesh filename="package://cyton_gamma_1500_description/meshes/shoulder_roll.dae"/>
      </geometry>
    </collision>
  </link> 

  <joint name="left_arm_shoulder_pitch_joint" type="revolute">
    <parent link="left_arm_shoulder_roll"/>
    <child link="left_arm_shoulder_pitch"/>
    <origin rpy="0 0 0" xyz="0.0205 0 0.12435"/>
    <limit effort="1000.0" lower="-1.8326" upper="1.8326" velocity="1.0"/>
    <axis xyz="1 0 0"/>
  </joint>
  <link name="left_arm_shoulder_pitch">
    <inertial>
      <origin rpy="0 0 0" xyz="-0.0214 0 0.117"/>
      <mass value="0.4285714"/>
      <!-- inretia tensor for solid cylinder: m=0.4285714, h=0.09248, r=0.04204 -->
      <inertia ixx="4.9e-04" ixy="0" ixz="0" iyy="3.8e-04" iyz="0" izz="4.9e-04"/>
    </inertial>
    <visual>
      <origin rpy="1.5708 0 0" xyz="0 0 0"/>
      <geometry>
        <mesh filename="package://cyton_gamma_1500_description/meshes/shoulder_pitch.dae"/>
      </geometry>
    </visual>
    <collision>
      <origin rpy="1.5708 0 0" xyz="0 0 0"/>
      <geometry>
        <mesh filename="package://cyton_gamma_1500_description/meshes/shoulder_pitch.dae"/>
      </geometry>
    </collision>
  </link>

  <joint name="left_arm_shoulder_yaw_joint" type="revolute">
    <parent link="left_arm_shoulder_pitch"/>
    <child link="left_arm_shoulder_yaw"/>
    <origin rpy="0 0 0" xyz="-0.0215 -0.0205 0.1255"/>
    <limit effort="1000.0" lower="-1.8326" upper="1.8326" velocity="1.0"/>
    <axis xyz="0 -1 0"/>
  </joint>
  <link name="left_arm_shoulder_yaw">
    <inertial>
      <origin rpy="0 0 0" xyz="-0.002 0.021 0.1135"/>
      <mass value="0.408571"/>
      <!-- inretia tensor for solid cylinder: m=0.408571, h=0.084081, r=0.036785 -->
      <inertia ixx="2.8e-04" ixy="0" ixz="0" iyy="3.8e-04" iyz="0" izz="3.8e-04"/>
    </inertial>
    <visual>
      <origin rpy="1.5708 0 -1.5708" xyz="0 0 0"/>
      <geometry>
        <mesh filename="package://cyton_gamma_1500_description/meshes/shoulder_yaw.dae"/>
      </geometry>
    </visual>
    <collision>
      <origin rpy="1.5708 0 -1.5708" xyz="0 0 0"/>
      <geometry>
        <mesh filename="package://cyton_gamma_1500_description/meshes/shoulder_yaw.dae"/>
      </geometry>
    </collision>
  </link>

  <joint name="left_arm_elbow_pitch_joint" type="revolute">
    <parent link="left_arm_shoulder_yaw"/>
    <child link="left_arm_elbow_pitch"/>
    <origin rpy="0 0 0" xyz="0.018 0.0206 0.1158"/>
    <limit effort="1000.0" lower="-1.8326" upper="1.8326" velocity="1.0"/>
    <axis xyz="1 0 0"/>
  </joint>
  <link name="left_arm_elbow_pitch">
    <inertial>
      <origin rpy="0 0 0" xyz="-0.0176 0.001 0.095"/>
      <mass value="0.388671"/>
      <!-- inretia tensor for solid cylinder: m=0.388671, h=0.06705, r=0.028975 -->
      <inertia ixx="2.3e-04" ixy="0" ixz="0" iyy="1.6e-04" iyz="0" izz="2.3e-04"/>
    </inertial>
    <visual>
      <origin rpy="1.5708 0 3.1416" xyz="0 0 0"/>
      <geometry>
        <mesh filename="package://cyton_gamma_1500_description/meshes/elbow_pitch.dae"/>
      </geometry>
    </visual>
    <collision>
      <origin rpy="1.5708 0 3.1416" xyz="0 0 0"/>
      <geometry>
        <mesh filename="package://cyton_gamma_1500_description/meshes/elbow_pitch.dae"/>
      </geometry>
    </collision>
  </link>

  <joint name="left_arm_elbow_yaw_joint" type="revolute">
    <parent link="left_arm_elbow_pitch"/>
    <child link="left_arm_elbow_yaw"/>
    <origin rpy="0 0 0" xyz="-0.0171 -0.018 0.09746"/>
    <limit effort="1000.0" lower="-1.8326" upper="1.8326" velocity="1.0"/>
    <axis xyz="0 -1 0"/>
  </joint>
  <link name="left_arm_elbow_yaw">
    <inertial>
      <origin rpy="0 0 0" xyz="0 0.018 0.073"/>
      <mass value="0.368871"/>
      <!-- inretia tensor for solid cylinder: m=0.368871, h=0.043602, r=0.024071 -->
      <inertia ixx="1.0686e-04" ixy="0" ixz="0" iyy="1.1187e-04" iyz="0" izz="1.1187e-04"/>
    </inertial>
    <visual>
      <origin rpy="1.5708 0 1.5708" xyz="0 0 0"/>
      <geometry>
        <mesh filename="package://cyton_gamma_1500_description/meshes/elbow_yaw.dae"/>
      </geometry>
    </visual>
    <collision>
      <origin rpy="1.5708 0 1.5708" xyz="0 0 0"/>
      <geometry>
        <mesh filename="package://cyton_gamma_1500_description/meshes/elbow_yaw.dae"/>
      </geometry>
    </collision>
  </link>

  <joint name="left_arm_wrist_pitch_joint" type="revolute">
    <parent link="left_arm_elbow_yaw"/>
    <child link="left_arm_wrist_pitch"/>
    <origin rpy="0 0 0" xyz="0.02626 0.018 0.0718"/>
    <limit effort="100.0" lower="-1.8326" upper="1.8326" velocity="1.0"/>
    <axis xyz="-1 0 0"/>
  </joint>
  <link name="left_arm_wrist_pitch">
    <inertial>
      <origin rpy="0 0 0" xyz="-0.027 -0.0005 0.028"/>
      <mass value="0.008"/>
      <!-- inretia tensor for solid cuboid: m=0.008, h=0.045602, w=0.0218, d=0.005 -->
      <inertia ixx="3.3349e-07" ixy="0" ixz="0" iyy="1.403e-06" iyz="0" izz="1.70319e-06"/>
    </inertial>
    <visual>
      <origin rpy="1.5708 0 1.5708" xyz="0 0 0"/>
      <geometry>
        <mesh filename="package://cyton_gamma_1500_description/meshes/wrist_pitch.dae"/>
      </geometry>
    </visual>
    <collision>
      <origin rpy="1.5708 0 1.5708" xyz="0 0 0"/>
      <geometry>
        <mesh filename="package://cyton_gamma_1500_description/meshes/wrist_pitch.dae"/>
      </geometry>
    </collision>
  </link>

  <joint name="left_arm_wrist_roll_joint" type="revolute">
    <parent link="left_arm_wrist_pitch"/>
    <child link="left_arm_wrist_roll"/>
    <origin rpy="0 0 0" xyz="-0.026255 0 0.051425"/>
    <limit effort="100.0" lower="-2.61799" upper="2.61799" velocity="1.0"/>
    <axis xyz="0 0 1"/>
  </joint>
  <link name="left_arm_wrist_roll">
    <inertial>
      <origin rpy="0 0 0" xyz="0 0 0.029"/>
      <mass value="0.38"/>
      <!-- inretia tensor for solid cylinder: m=0.38, h=0.095, r=0.027975 -->
      <inertia ixx="3.6e-04" ixy="0" ixz="0" iyy="3.6e-04" iyz="0" izz="1.487e-04"/>
    </inertial>
    <visual>
      <origin rpy="3.1416 0 -1.5708" xyz="0 0 0"/>
      <geometry>
        <mesh filename="package://cyton_gamma_1500_description/meshes/wrist_roll.dae"/>
      </geometry>
    </visual>
    <collision>
      <origin rpy="3.1416 0 -1.5708" xyz="0 0 0"/>
      <geometry>
        <mesh filename="package://cyton_gamma_1500_description/meshes/wrist_roll.dae"/>
      </geometry>
    </collision>
  </link>

  <joint name="left_arm_gripper_joint" type="prismatic">
    <parent link="left_arm_wrist_roll"/>
    <child link="left_arm_gripper_finger1"/>
    <origin rpy="0 0 0" xyz="-0.01331 0.00485 0.077225"/>
    <limit effort="200.0" lower="-0.008" upper="0.008" velocity="1.0"/>
    <axis xyz="1 0 0"/>
  </joint>
  <link name="left_arm_gripper_finger1">
    <inertial>
      <origin rpy="0 0 0" xyz="-0.0036 0.0096 0.017"/>
      <mass value="0.035"/>
      <!-- inretia tensor for solid cuboid: m=0.035, h=0.0323, w=0.01469, d=0.0224 -->
      <inertia ixx="4.5064e-06" ixy="0" ixz="0" iyy="3.6723e-06" iyz="0" izz="2.0929e-06"/>
    </inertial>
    <visual>
      <origin rpy="0 0 0" xyz="0 0 0"/>
      <geometry>
        <mesh filename="package://cyton_gamma_1500_description/meshes/gripper_finger1.dae"/>
      </geometry>
    </visual>
    <collision>
      <origin rpy="0 0 0" xyz="0 0 0"/>
      <geometry>
        <mesh filename="package://cyton_gamma_1500_description/meshes/gripper_finger1.dae"/>
      </geometry>
    </collision>
  </link>

  <joint name="left_arm_gripper_joint2" type="prismatic">
    <parent link="left_arm_wrist_roll"/>
    <child link="left_arm_gripper_finger2"/>
    <origin rpy="0 0 0" xyz="0.0098 0.00485 0.077225"/>
    <limit effort="200.0" lower="-0.008" upper="0.008" velocity="1.0"/>
    <mimic joint="left_arm_gripper_joint" multiplier="-1"/>
    <axis xyz="1 0 0"/>
  </joint>
  <link name="left_arm_gripper_finger2">
    <inertial>
      <origin rpy="0 0 0" xyz="0.0034 0.0096 0.017"/>
      <mass value="0.035"/>
      <!-- inretia tensor for solid cuboid: m=0.035, h=0.0323, w=0.01469, d=0.0224 -->
      <inertia ixx="4.5064e-06" ixy="0" ixz="0" iyy="3.6723e-06" iyz="0" izz="2.0929e-06"/>
    </inertial>
    <visual>
      <origin rpy="0 0 0" xyz="0 0 0"/>
      <geometry>
        <mesh filename="package://cyton_gamma_1500_description/meshes/gripper_finger2.dae"/>
      </geometry>
    </visual>
    <collision>
      <origin rpy="0 0 0" xyz="0 0 0"/>
      <geometry>
        <mesh filename="package://cyton_gamma_1500_description/meshes/gripper_finger2.dae"/>
      </geometry>
    </collision>
  </link>

  <!-- camera and camera bracket -->
  <joint name="left_arm_camera_bracket_joint" type="fixed">
    <parent link="left_arm_wrist_roll"/>
    <child link="left_arm_camera_bracket"/>
    <origin rpy="0 0 0" xyz="-0.0008 -0.028 0.0435"/>
  </joint>
  <link name="left_arm_camera_bracket">
    <inertial>
      <origin rpy="0.95 0 0" xyz="0 -0.01 -0.012"/>
      <mass value="0.052"/>
      <!-- inretia tensor for solid cuboid: m=0.052, h=0.071, w=0.028, d=0.0086 -->
      <inertia ixx="2.2165e-05" ixy="0" ixz="0" iyy="3.7178e-06" iyz="0" izz="2.5242e-05"/>
    </inertial>
    <visual>
      <origin rpy="0 0 0" xyz="0 0 0"/>
      <geometry>
        <mesh filename="package://cyton_gamma_1500_minicam_description/meshes/cam_bracket.dae"/>
      </geometry>
    </visual>
    <collision>
      <origin rpy="0 0 0" xyz="0 0 0"/>
      <geometry>
        <mesh filename="package://cyton_gamma_1500_minicam_description/meshes/cam_bracket.dae"/>
      </geometry>
    </collision>
  </link>

  <joint name="left_arm_camera_joint" type="fixed">
    <parent link="left_arm_camera_bracket"/>
    <child link="left_arm_camera"/>
    <origin rpy="-0.625 0 0" xyz="0.0 -0.028 -0.005"/>
  </joint>
  <link name="left_arm_camera">
    <inertial>
      <origin rpy="0 0 0" xyz="0 0 0"/>
      <mass value="0.085"/>
      <!-- inretia tensor for solid cuboid: m=0.085, h=0.065, w=0.024, d=0.024 -->
      <inertia ixx="3.4007e-05" ixy="0" ixz="0" iyy="3.4007e-05" iyz="0" izz="8.16e-06"/>
    </inertial>
    <visual>
      <origin rpy="0 0 0" xyz="0 0 0"/>
      <geometry>
        <box size="0.031 0.028 0.063"/>
      </geometry>
      <material name="blackish">
        <color rgba="0.2 0.2 0.2 1"/>
      </material>
    </visual>
    <collision>
      <origin rpy="0 0 0" xyz="0 0 0"/>
      <geometry>
        <box size="0.036 0.045 0.063"/>
      </geometry>
    </collision>
  </link>

<!-- PTU -->

  <joint name="ptu_joint" type="fixed">
    <parent link="top_lidar_link"/>
    <child link="ptu_base_plate_link"/>
    <origin rpy="0 0 0" xyz="0.12 0.0 0.03"/>
  </joint>
  <link name="ptu_base_plate_link">
    <inertial>
      <origin rpy="0 0 0" xyz="-0.034 0 0"/>
      <mass value="0.07"/>
      <!-- inretia tensor for solid cuboid: m=0.07, h=0.005, w=0.142, d=0.17 -->
      <inertia ixx="1.1777e-04" ixy="0" ixz="0" iyy="1.6873e-04" iyz="0" izz="2.8621e-04"/>
    </inertial>
    <visual>
      <origin rpy="0 0 0" xyz="-0.035 0 0.0025"/>
      <geometry>
        <box size="0.17 0.142 0.005"/>
      </geometry>
      <material name="black">
        <color rgba="0.2 0.2 0.2 1"/>
      </material>
    </visual>
    <collision>
      <origin rpy="0 0 0" xyz="-0.035 0 0.0025"/>
      <geometry>
        <box size="0.17 0.142 0.005"/>
      </geometry>
    </collision>
  </link>

  <joint name="ptu_base_joint" type="fixed">
    <parent link="ptu_base_plate_link"/>
    <child link="ptu_pan_link"/>
    <origin rpy="0 0 0" xyz="0.0 0 0.005"/>
  </joint>
  <link name="ptu_pan_link">
    <inertial>
      <origin rpy="0 0 0" xyz="0 0 0.06"/>
      <mass value="0.13"/>
      <!-- inretia tensor for solid cuboid: m=0.13, h=0.07, w=0.046, d=0.105 -->
      <inertia ixx="7.6006e-05" ixy="0" ixz="0" iyy="1.4136e-04" iyz="0" izz="1.7892e-04"/>
    </inertial>
    <visual>
      <origin rpy="0 0 0" xyz="0 0 0.025"/>
      <geometry>
        <mesh filename="package://dp_ptu_46_description/meshes/pan.dae"/>
      </geometry>
    </visual>
    <collision>
      <origin rpy="0 0 0" xyz="0 0 0.025"/>
      <geometry>
        <mesh filename="package://dp_ptu_46_description/meshes/pan.dae"/>
      </geometry>
    </collision>
  </link>

  <joint name="ptu_pan_joint" type="revolute">
    <parent link="ptu_pan_link"/>
    <child link="ptu_tilt_link"/>
    <origin rpy="0 0 0" xyz="-0.00436 -0.0067 0.03"/>
    <limit effort="100.0" lower="-2.775" upper="2.775" velocity="1.0"/>
    <axis xyz="0 0 1"/>
  </joint>
  <link name="ptu_tilt_link">
    <inertial>
      <origin rpy="0 0 0" xyz="-0.03 0 0.05"/>
      <mass value="0.13"/>
      <!-- inretia tensor for solid cuboid: m=0.13, h=0.07, w=0.046, d=0.105 -->
      <inertia ixx="7.6006e-05" ixy="0" ixz="0" iyy="1.7252e-04" iyz="0" izz="1.4136e-04"/>
    </inertial>
    <visual>
      <origin rpy="0 0 0" xyz="0.00436 0.0067 0"/>
      <geometry>
        <mesh filename="package://dp_ptu_46_description/meshes/tilt.dae"/>
      </geometry>
    </visual>
    <collision>
      <origin rpy="0 0 0" xyz="0.00436 0.0067 0"/>
      <geometry>
        <mesh filename="package://dp_ptu_46_description/meshes/tilt.dae"/>
      </geometry>
    </collision>
  </link>

  <joint name="ptu_tilt_joint" type="revolute">
    <parent link="ptu_tilt_link"/>
    <child link="ptu_mount_link"/>
    <origin rpy="0 0 0" xyz="0.0 0 0.0659"/>
    <limit effort="100.0" lower="-1.396" upper="0.541" velocity="1.0"/>
    <axis xyz="0 -1 0"/>
  </joint>
  <link name="ptu_mount_link">
    <inertial>
      <origin rpy="0 0 0" xyz="0 0 0.036"/>
      <mass value="0.07"/>
      <!-- inretia tensor for solid cuboid: m=0.07, h=0.007, w=0.052, d=0.025 -->
      <inertia ixx="1.6059e-05" ixy="0" ixz="0" iyy="3.9316e-06" iyz="0" izz="1.9419e-05"/>
    </inertial>
    <visual>
      <origin rpy="0 0 0" xyz="0.00436 0.0067 -0.0659"/>
      <geometry>
        <mesh filename="package://dp_ptu_46_description/meshes/mount.dae"/>
      </geometry>
    </visual>
    <collision>
      <origin rpy="0 0 0" xyz="0.00436 0.0067 -0.0659"/>
      <geometry>
        <mesh filename="package://dp_ptu_46_description/meshes/mount.dae"/>
      </geometry>
    </collision>
  </link>

<!-- Hokuyo lidar -->

  <joint name="hokuyo_base_joint" type="fixed">
    <parent link="bot_base_link"/>
    <child link="hokuyo_link"/>
    <origin rpy="0 0 0" xyz="0.1 0 0.29"/>
  </joint>
  <link name="hokuyo_link">
    <inertial>
      <origin rpy="0 0 0" xyz="0 0 -0.02"/>
      <mass value="0.13"/>
      <!-- inretia tensor for solid cuboid: m=0.13, h=0.07, w=0.05, d=0.05 -->
      <inertia ixx="8.0167e-05" ixy="0" ixz="0" iyy="8.0167e-05" iyz="0" izz="5.4167e-05"/>
    </inertial>
    <visual>
      <origin rpy="0 0 0" xyz="0 0 0"/>
      <geometry>
        <cylinder length="0.0265" radius="0.021"/>
      </geometry>
      <material name="blackish"/>
    </visual>
    <visual>
      <origin rpy="0 0 0" xyz="0 0 -0.034"/>
      <geometry>
        <box size="0.05 0.05 0.041"/>
      </geometry>
      <material name="blackish"/>
    </visual>
    <collision>
      <origin rpy="0 0 0" xyz="0 0 0"/>
      <geometry>
        <cylinder length="0.0265" radius="0.021"/>
      </geometry>
    </collision>
    <collision>
      <origin rpy="0 0 0" xyz="0 0 -0.047"/>
      <geometry>
        <box size="0.05 0.05 0.041"/>
      </geometry>
    </collision>
  </link>

</robot>
